Workbook

Sheet GPA Calculator & Simulator (4Y)
C3: Summary | F3: GPA Calculator - حاسبة المعدل التراكمي | L3: ملخص عام
C4: Total Credit Hours | D4: =F22+L22+F39+L39+F56+L56+F73+L73 -> 0 | F4: Made with ❤️ for Faculty Students by | L4: =F22+L22+F39+L39+F56+L56+F73+L73 -> 0 | M4: إجمالي عدد الساعات
C5: Cumulative GPA of All Years | D5: =IFERROR( (IF(ISNUMBER(F22*F23), F22*F23, 0) + IF(ISNUMBER(L22*L23), L22*L23, 0) + IF(ISNUMBER(F39*F40), F39*F40, 0) + IF(ISNUMBER(L39*L40), L39*L40, 0) + IF(ISNUMBER(F56*F57), F56*F57, 0) + IF(ISNUMBER(L56*L57), L56*L57, 0) + IF(ISNUMBER(F73*F74), F73*F74, 0) + IF(ISNUMBER(L73*L74), L73*L74, 0)) / (IF(ISNUMBER(F22), F22, 0) + IF(ISNUMBER(L22), L22, 0) + IF(ISNUMBER(F39), F39, 0) + IF(ISNUMBER(L39), L39, 0) + IF(ISNUMBER(F56), F56, 0) + IF(ISNUMBER(L56), L56, 0) + IF(ISNUMBER(F73), F73, 0) + IF(ISNUMBER(L73), L73, 0)), 0) -> 0 | L5: =IFERROR( (IF(ISNUMBER(F22*F23), F22*F23, 0) + IF(ISNUMBER(L22*L23), L22*L23, 0) + IF(ISNUMBER(F39*F40), F39*F40, 0) + IF(ISNUMBER(L39*L40), L39*L40, 0) + IF(ISNUMBER(F56*F57), F56*F57, 0) + IF(ISNUMBER(L56*L57), L56*L57, 0) + IF(ISNUMBER(F73*F74), F73*F74, 0) + IF(ISNUMBER(L73*L74), L73*L74, 0)) / (IF(ISNUMBER(F22), F22, 0) + IF(ISNUMBER(L22), L22, 0) + IF(ISNUMBER(F39), F39, 0) + IF(ISNUMBER(L39), L39, 0) + IF(ISNUMBER(F56), F56, 0) + IF(ISNUMBER(L56), L56, 0) + IF(ISNUMBER(F73), F73, 0) + IF(ISNUMBER(L73), L73, 0)), 0) -> 0 | M5: المعدل التراكمي العام
B8: Year 1
C10: Term 1 | I10: Term 2
C11: Course | D11: Credits | E11: Grade | F11: Point | G11: Total | I11: Course | J11: Credits | K11: Grade | L11: Point | M11: Total
F12: =IF(E12="", "", VLOOKUP(E12, GradingTable!$A$2:$B$14, 2, FALSE)) | G12: =IF(AND(ISNUMBER(D12),ISNUMBER(F12)),D12*F12,"") | L12: =IF(K12="", "", VLOOKUP(K12, GradingTable!$A$2:$B$14, 2, FALSE)) | M12: =IF(AND(ISNUMBER(J12),ISNUMBER(L12)),J12*L12,"")
F13: =IF(E13="", "", VLOOKUP(E13, GradingTable!$A$2:$B$14, 2, FALSE)) | G13: =IF(AND(ISNUMBER(D13),ISNUMBER(F13)),D13*F13,"") | L13: =IF(K13="", "", VLOOKUP(K13, GradingTable!$A$2:$B$14, 2, FALSE)) | M13: =IF(AND(ISNUMBER(J13),ISNUMBER(L13)),J13*L13,"")
F14: =IF(E14="", "", VLOOKUP(E14, GradingTable!$A$2:$B$14, 2, FALSE)) | G14: =IF(AND(ISNUMBER(D14),ISNUMBER(F14)),D14*F14,"") | L14: =IF(K14="", "", VLOOKUP(K14, GradingTable!$A$2:$B$14, 2, FALSE)) | M14: =IF(AND(ISNUMBER(J14),ISNUMBER(L14)),J14*L14,"") | O14: Year 1 Hours
F15: =IF(E15="", "", VLOOKUP(E15, GradingTable!$A$2:$B$14, 2, FALSE)) | G15: =IF(AND(ISNUMBER(D15),ISNUMBER(F15)),D15*F15,"") | L15: =IF(K15="", "", VLOOKUP(K15, GradingTable!$A$2:$B$14, 2, FALSE)) | M15: =IF(AND(ISNUMBER(J15),ISNUMBER(L15)),J15*L15,"") | O15: =SUM(F22+L22) -> 0
F16: =IF(E16="", "", VLOOKUP(E16, GradingTable!$A$2:$B$14, 2, FALSE)) | G16: =IF(AND(ISNUMBER(D16),ISNUMBER(F16)),D16*F16,"") | L16: =IF(K16="", "", VLOOKUP(K16, GradingTable!$A$2:$B$14, 2, FALSE)) | M16: =IF(AND(ISNUMBER(J16),ISNUMBER(L16)),J16*L16,"")
F17: =IF(E17="", "", VLOOKUP(E17, GradingTable!$A$2:$B$14, 2, FALSE)) | G17: =IF(AND(ISNUMBER(D17),ISNUMBER(F17)),D17*F17,"") | L17: =IF(K17="", "", VLOOKUP(K17, GradingTable!$A$2:$B$14, 2, FALSE)) | M17: =IF(AND(ISNUMBER(J17),ISNUMBER(L17)),J17*L17,"") | O17: Year 1 cGPA
F18: =IF(E18="", "", VLOOKUP(E18, GradingTable!$A$2:$B$14, 2, FALSE)) | G18: =IF(AND(ISNUMBER(D18),ISNUMBER(F18)),D18*F18,"") | L18: =IF(K18="", "", VLOOKUP(K18, GradingTable!$A$2:$B$14, 2, FALSE)) | M18: =IF(AND(ISNUMBER(J18),ISNUMBER(L18)),J18*L18,"") | O18: =IFERROR( (IF(ISNUMBER(F22*F23), F22*F23, 0) + IF(ISNUMBER(L22*L23), L22*L23, 0)) / (IF(ISNUMBER(F22), F22, 0) + IF(ISNUMBER(L22), L22, 0)), 0) -> 0
F19: =IF(E19="", "", VLOOKUP(E19, GradingTable!$A$2:$B$14, 2, FALSE)) | G19: =IF(AND(ISNUMBER(D19),ISNUMBER(F19)),D19*F19,"") | L19: =IF(K19="", "", VLOOKUP(K19, GradingTable!$A$2:$B$14, 2, FALSE)) | M19: =IF(AND(ISNUMBER(J19),ISNUMBER(L19)),J19*L19,"")
F20: =IF(E20="", "", VLOOKUP(E20, GradingTable!$A$2:$B$14, 2, FALSE)) | G20: =IF(AND(ISNUMBER(D20),ISNUMBER(F20)),D20*F20,"") | L20: =IF(K20="", "", VLOOKUP(K20, GradingTable!$A$2:$B$14, 2, FALSE)) | M20: =IF(AND(ISNUMBER(J20),ISNUMBER(L20)),J20*L20,"")
D22: Total Term Hours | F22: =SUM(D12:D21) -> 0 | J22: Total Term Hours | L22: =SUM(J12:J21) -> 0
D23: Term GPA | F23: =IF(F22=0, "", SUM(G12:G21)/F22) | J23: Term GPA | L23: =IF(L22=0, "", SUM(M12:M21)/L22)
B25: Year 2
C27: Term 3 | I27: Term 4
C28: Course | D28: Credits | E28: Grade | F28: Point | G28: Total | I28: Course | J28: Credits | K28: Grade | L28: Point | M28: Total
F29: =IF(E29="", "", VLOOKUP(E29, GradingTable!$A$2:$B$14, 2, FALSE)) | G29: =IF(AND(ISNUMBER(D29),ISNUMBER(F29)),D29*F29,"") | L29: =IF(K29="", "", VLOOKUP(K29, GradingTable!$A$2:$B$14, 2, FALSE)) | M29: =IF(AND(ISNUMBER(J29),ISNUMBER(L29)),J29*L29,"")
F30: =IF(E30="", "", VLOOKUP(E30, GradingTable!$A$2:$B$14, 2, FALSE)) | G30: =IF(AND(ISNUMBER(D30),ISNUMBER(F30)),D30*F30,"") | L30: =IF(K30="", "", VLOOKUP(K30, GradingTable!$A$2:$B$14, 2, FALSE)) | M30: =IF(AND(ISNUMBER(J30),ISNUMBER(L30)),J30*L30,"")
F31: =IF(E31="", "", VLOOKUP(E31, GradingTable!$A$2:$B$14, 2, FALSE)) | G31: =IF(AND(ISNUMBER(D31),ISNUMBER(F31)),D31*F31,"") | L31: =IF(K31="", "", VLOOKUP(K31, GradingTable!$A$2:$B$14, 2, FALSE)) | M31: =IF(AND(ISNUMBER(J31),ISNUMBER(L31)),J31*L31,"") | O31: Year 2 Hours
F32: =IF(E32="", "", VLOOKUP(E32, GradingTable!$A$2:$B$14, 2, FALSE)) | G32: =IF(AND(ISNUMBER(D32),ISNUMBER(F32)),D32*F32,"") | L32: =IF(K32="", "", VLOOKUP(K32, GradingTable!$A$2:$B$14, 2, FALSE)) | M32: =IF(AND(ISNUMBER(J32),ISNUMBER(L32)),J32*L32,"") | O32: =SUM(F39+L39) -> 0
F33: =IF(E33="", "", VLOOKUP(E33, GradingTable!$A$2:$B$14, 2, FALSE)) | G33: =IF(AND(ISNUMBER(D33),ISNUMBER(F33)),D33*F33,"") | L33: =IF(K33="", "", VLOOKUP(K33, GradingTable!$A$2:$B$14, 2, FALSE)) | M33: =IF(AND(ISNUMBER(J33),ISNUMBER(L33)),J33*L33,"")
F34: =IF(E34="", "", VLOOKUP(E34, GradingTable!$A$2:$B$14, 2, FALSE)) | G34: =IF(AND(ISNUMBER(D34),ISNUMBER(F34)),D34*F34,"") | L34: =IF(K34="", "", VLOOKUP(K34, GradingTable!$A$2:$B$14, 2, FALSE)) | M34: =IF(AND(ISNUMBER(J34),ISNUMBER(L34)),J34*L34,"") | O34: Year 2 cGPA
F35: =IF(E35="", "", VLOOKUP(E35, GradingTable!$A$2:$B$14, 2, FALSE)) | G35: =IF(AND(ISNUMBER(D35),ISNUMBER(F35)),D35*F35,"") | L35: =IF(K35="", "", VLOOKUP(K35, GradingTable!$A$2:$B$14, 2, FALSE)) | M35: =IF(AND(ISNUMBER(J35),ISNUMBER(L35)),J35*L35,"") | O35: =IFERROR( (IF(ISNUMBER(F39*F40), F39*F40, 0) + IF(ISNUMBER(L39*L40), L39*L40, 0)) / (IF(ISNUMBER(F39), F39, 0) + IF(ISNUMBER(L39), L39, 0)), 0) -> 0
F36: =IF(E36="", "", VLOOKUP(E36, GradingTable!$A$2:$B$14, 2, FALSE)) | G36: =IF(AND(ISNUMBER(D36),ISNUMBER(F36)),D36*F36,"") | L36: =IF(K36="", "", VLOOKUP(K36, GradingTable!$A$2:$B$14, 2, FALSE)) | M36: =IF(AND(ISNUMBER(J36),ISNUMBER(L36)),J36*L36,"")
F37: =IF(E37="", "", VLOOKUP(E37, GradingTable!$A$2:$B$14, 2, FALSE)) | G37: =IF(AND(ISNUMBER(D37),ISNUMBER(F37)),D37*F37,"") | L37: =IF(K37="", "", VLOOKUP(K37, GradingTable!$A$2:$B$14, 2, FALSE)) | M37: =IF(AND(ISNUMBER(J37),ISNUMBER(L37)),J37*L37,"")
D39: Total Term Hours | F39: =SUM(D29:D38) -> 0 | J39: Total Term Hours | L39: =SUM(J29:J38) -> 0
D40: Term GPA | F40: =IF(F39=0, "", SUM(G29:G38)/F39) | J40: Term GPA | L40: =IF(L39=0, "", SUM(M29:M38)/L39)
B42: Year 3
C44: Term 5 | I44: Term 6
C45: Course | D45: Credits | E45: Grade | F45: Point | G45: Total | I45: Course | J45: Credits | K45: Grade | L45: Point | M45: Total
F46: =IF(E46="", "", VLOOKUP(E46, GradingTable!$A$2:$B$14, 2, FALSE)) | G46: =IF(AND(ISNUMBER(D46),ISNUMBER(F46)),D46*F46,"") | L46: =IF(K46="", "", VLOOKUP(K46, GradingTable!$A$2:$B$14, 2, FALSE)) | M46: =IF(AND(ISNUMBER(J46),ISNUMBER(L46)),J46*L46,"")
F47: =IF(E47="", "", VLOOKUP(E47, GradingTable!$A$2:$B$14, 2, FALSE)) | G47: =IF(AND(ISNUMBER(D47),ISNUMBER(F47)),D47*F47,"") | L47: =IF(K47="", "", VLOOKUP(K47, GradingTable!$A$2:$B$14, 2, FALSE)) | M47: =IF(AND(ISNUMBER(J47),ISNUMBER(L47)),J47*L47,"")
F48: =IF(E48="", "", VLOOKUP(E48, GradingTable!$A$2:$B$14, 2, FALSE)) | G48: =IF(AND(ISNUMBER(D48),ISNUMBER(F48)),D48*F48,"") | L48: =IF(K48="", "", VLOOKUP(K48, GradingTable!$A$2:$B$14, 2, FALSE)) | M48: =IF(AND(ISNUMBER(J48),ISNUMBER(L48)),J48*L48,"") | O48: Year 3 Hours
F49: =IF(E49="", "", VLOOKUP(E49, GradingTable!$A$2:$B$14, 2, FALSE)) | G49: =IF(AND(ISNUMBER(D49),ISNUMBER(F49)),D49*F49,"") | L49: =IF(K49="", "", VLOOKUP(K49, GradingTable!$A$2:$B$14, 2, FALSE)) | M49: =IF(AND(ISNUMBER(J49),ISNUMBER(L49)),J49*L49,"") | O49: =SUM(F56+L56) -> 0
F50: =IF(E50="", "", VLOOKUP(E50, GradingTable!$A$2:$B$14, 2, FALSE)) | G50: =IF(AND(ISNUMBER(D50),ISNUMBER(F50)),D50*F50,"") | L50: =IF(K50="", "", VLOOKUP(K50, GradingTable!$A$2:$B$14, 2, FALSE)) | M50: =IF(AND(ISNUMBER(J50),ISNUMBER(L50)),J50*L50,"")
F51: =IF(E51="", "", VLOOKUP(E51, GradingTable!$A$2:$B$14, 2, FALSE)) | G51: =IF(AND(ISNUMBER(D51),ISNUMBER(F51)),D51*F51,"") | L51: =IF(K51="", "", VLOOKUP(K51, GradingTable!$A$2:$B$14, 2, FALSE)) | M51: =IF(AND(ISNUMBER(J51),ISNUMBER(L51)),J51*L51,"") | O51: Year 3 cGPA
...

Sheet GPA Calculator & Simulator (5Y)
C3: Summary | F3: GPA Calculator - حاسبة المعدل التراكمي | L3: ملخص عام
C4: Total Credit Hours | D4: =F22+L22+F39+L39+F56+L56+F73+L73+F90+L90 -> 8 | F4: Made with ❤️ for Faculty Students by | L4: =F22+L22+F39+L39+F56+L56+F73+L73+F90+L90 -> 8 | M4: إجمالي عدد الساعات
C5: Cumulative GPA of All Years | D5: =IFERROR( (IF(ISNUMBER(F22*F23), F22*F23, 0) + IF(ISNUMBER(L22*L23), L22*L23, 0) + IF(ISNUMBER(F39*F40), F39*F40, 0) + IF(ISNUMBER(L39*L40), L39*L40, 0) + IF(ISNUMBER(F56*F57), F56*F57, 0) + IF(ISNUMBER(L56*L57), L56*L57, 0) + IF(ISNUMBER(F73*F74), F73*F74, 0) + IF(ISNUMBER(L73*L74), L73*L74, 0) + IF(ISNUMBER(F90*F91), F90*F91, 0) + IF(ISNUMBER(L90*L91), L90*L91, 0)) / (IF(ISNUMBER(F22), F22, 0) + IF(ISNUMBER(L22), L22, 0) + IF(ISNUMBER(F39), F39, 0) + IF(ISNUMBER(L39), L39, 0) + IF(ISNUMBER(F56), F56, 0) + IF(ISNUMBER(L56), L56, 0) + IF(ISNUMBER(F73), F73, 0) + IF(ISNUMBER(L73), L73, 0) + IF(ISNUMBER(F90), F90, 0) + IF(ISNUMBER(L90), L90, 0)), 0) -> 3.825 | L5: =IFERROR( (IF(ISNUMBER(F22*F23), F22*F23, 0) + IF(ISNUMBER(L22*L23), L22*L23, 0) + IF(ISNUMBER(F39*F40), F39*F40, 0) + IF(ISNUMBER(L39*L40), L39*L40, 0) + IF(ISNUMBER(F56*F57), F56*F57, 0) + IF(ISNUMBER(L56*L57), L56*L57, 0) + IF(ISNUMBER(F73*F74), F73*F74, 0) + IF(ISNUMBER(L73*L74), L73*L74, 0) + IF(ISNUMBER(F90*F91), F90*F91, 0) + IF(ISNUMBER(L90*L91), L90*L91, 0)) / (IF(ISNUMBER(F22), F22, 0) + IF(ISNUMBER(L22), L22, 0) + IF(ISNUMBER(F39), F39, 0) + IF(ISNUMBER(L39), L39, 0) + IF(ISNUMBER(F56), F56, 0) + IF(ISNUMBER(L56), L56, 0) + IF(ISNUMBER(F73), F73, 0) + IF(ISNUMBER(L73), L73, 0) + IF(ISNUMBER(F90), F90, 0) + IF(ISNUMBER(L90), L90, 0)), 0) -> 3.825 | M5: المعدل التراكمي العام
B8: Year 1
C10: Term 1 | I10: Term 2
C11: Course | D11: Credits | E11: Grade | F11: Point | G11: Total | I11: Course | J11: Credits | K11: Grade | L11: Point | M11: Total
C12: Course1 | D12: 3 | E12: A | F12: =IF(E12="", "", VLOOKUP(E12, GradingTable!$A$2:$B$14, 2, FALSE)) -> 4 | G12: =IF(AND(ISNUMBER(D12),ISNUMBER(F12)),D12*F12,"") -> 12 | I12: Course1 | J12: 3 | K12: A | L12: =IF(K12="", "", VLOOKUP(K12, GradingTable!$A$2:$B$14, 2, FALSE)) -> 4 | M12: =IF(AND(ISNUMBER(J12),ISNUMBER(L12)),J12*L12,"") -> 12
C13: Course2 | D13: 2 | E13: B+ | F13: =IF(E13="", "", VLOOKUP(E13, GradingTable!$A$2:$B$14, 2, FALSE)) -> 3.3 | G13: =IF(AND(ISNUMBER(D13),ISNUMBER(F13)),D13*F13,"") -> 6.6 | L13: =IF(K13="", "", VLOOKUP(K13, GradingTable!$A$2:$B$14, 2, FALSE)) | M13: =IF(AND(ISNUMBER(J13),ISNUMBER(L13)),J13*L13,"")
F14: =IF(E14="", "", VLOOKUP(E14, GradingTable!$A$2:$B$14, 2, FALSE)) | G14: =IF(AND(ISNUMBER(D14),ISNUMBER(F14)),D14*F14,"") | L14: =IF(K14="", "", VLOOKUP(K14, GradingTable!$A$2:$B$14, 2, FALSE)) | M14: =IF(AND(ISNUMBER(J14),ISNUMBER(L14)),J14*L14,"") | O14: Year 1 Hours
F15: =IF(E15="", "", VLOOKUP(E15, GradingTable!$A$2:$B$14, 2, FALSE)) | G15: =IF(AND(ISNUMBER(D15),ISNUMBER(F15)),D15*F15,"") | L15: =IF(K15="", "", VLOOKUP(K15, GradingTable!$A$2:$B$14, 2, FALSE)) | M15: =IF(AND(ISNUMBER(J15),ISNUMBER(L15)),J15*L15,"") | O15: =SUM(F22+L22) -> 8
F16: =IF(E16="", "", VLOOKUP(E16, GradingTable!$A$2:$B$14, 2, FALSE)) | G16: =IF(AND(ISNUMBER(D16),ISNUMBER(F16)),D16*F16,"") | L16: =IF(K16="", "", VLOOKUP(K16, GradingTable!$A$2:$B$14, 2, FALSE)) | M16: =IF(AND(ISNUMBER(J16),ISNUMBER(L16)),J16*L16,"")
F17: =IF(E17="", "", VLOOKUP(E17, GradingTable!$A$2:$B$14, 2, FALSE)) | G17: =IF(AND(ISNUMBER(D17),ISNUMBER(F17)),D17*F17,"") | L17: =IF(K17="", "", VLOOKUP(K17, GradingTable!$A$2:$B$14, 2, FALSE)) | M17: =IF(AND(ISNUMBER(J17),ISNUMBER(L17)),J17*L17,"") | O17: Year 1 cGPA
F18: =IF(E18="", "", VLOOKUP(E18, GradingTable!$A$2:$B$14, 2, FALSE)) | G18: =IF(AND(ISNUMBER(D18),ISNUMBER(F18)),D18*F18,"") | L18: =IF(K18="", "", VLOOKUP(K18, GradingTable!$A$2:$B$14, 2, FALSE)) | M18: =IF(AND(ISNUMBER(J18),ISNUMBER(L18)),J18*L18,"") | O18: =IFERROR( (IF(ISNUMBER(F22*F23), F22*F23, 0) + IF(ISNUMBER(L22*L23), L22*L23, 0)) / (IF(ISNUMBER(F22), F22, 0) + IF(ISNUMBER(L22), L22, 0)), 0) -> 3.825
F19: =IF(E19="", "", VLOOKUP(E19, GradingTable!$A$2:$B$14, 2, FALSE)) | G19: =IF(AND(ISNUMBER(D19),ISNUMBER(F19)),D19*F19,"") | L19: =IF(K19="", "", VLOOKUP(K19, GradingTable!$A$2:$B$14, 2, FALSE)) | M19: =IF(AND(ISNUMBER(J19),ISNUMBER(L19)),J19*L19,"")
F20: =IF(E20="", "", VLOOKUP(E20, GradingTable!$A$2:$B$14, 2, FALSE)) | G20: =IF(AND(ISNUMBER(D20),ISNUMBER(F20)),D20*F20,"") | L20: =IF(K20="", "", VLOOKUP(K20, GradingTable!$A$2:$B$14, 2, FALSE)) | M20: =IF(AND(ISNUMBER(J20),ISNUMBER(L20)),J20*L20,"")
D22: Total Term Hours | F22: =SUM(D12:D21) -> 5 | J22: Total Term Hours | L22: =SUM(J12:J21) -> 3
D23: Term GPA | F23: =IF(F22=0, "", SUM(G12:G21)/F22) -> 3.72 | J23: Term GPA | L23: =IF(L22=0, "", SUM(M12:M21)/L22) -> 4
B25: Year 2
C27: Term 3 | I27: Term 4
C28: Course | D28: Credits | E28: Grade | F28: Point | G28: Total | I28: Course | J28: Credits | K28: Grade | L28: Point | M28: Total
F29: =IF(E29="", "", VLOOKUP(E29, GradingTable!$A$2:$B$14, 2, FALSE)) | G29: =IF(AND(ISNUMBER(D29),ISNUMBER(F29)),D29*F29,"") | L29: =IF(K29="", "", VLOOKUP(K29, GradingTable!$A$2:$B$14, 2, FALSE)) | M29: =IF(AND(ISNUMBER(J29),ISNUMBER(L29)),J29*L29,"")
F30: =IF(E30="", "", VLOOKUP(E30, GradingTable!$A$2:$B$14, 2, FALSE)) | G30: =IF(AND(ISNUMBER(D30),ISNUMBER(F30)),D30*F30,"") | L30: =IF(K30="", "", VLOOKUP(K30, GradingTable!$A$2:$B$14, 2, FALSE)) | M30: =IF(AND(ISNUMBER(J30),ISNUMBER(L30)),J30*L30,"")
F31: =IF(E31="", "", VLOOKUP(E31, GradingTable!$A$2:$B$14, 2, FALSE)) | G31: =IF(AND(ISNUMBER(D31),ISNUMBER(F31)),D31*F31,"") | L31: =IF(K31="", "", VLOOKUP(K31, GradingTable!$A$2:$B$14, 2, FALSE)) | M31: =IF(AND(ISNUMBER(J31),ISNUMBER(L31)),J31*L31,"") | O31: Year 2 Hours
F32: =IF(E32="", "", VLOOKUP(E32, GradingTable!$A$2:$B$14, 2, FALSE)) | G32: =IF(AND(ISNUMBER(D32),ISNUMBER(F32)),D32*F32,"") | L32: =IF(K32="", "", VLOOKUP(K32, GradingTable!$A$2:$B$14, 2, FALSE)) | M32: =IF(AND(ISNUMBER(J32),ISNUMBER(L32)),J32*L32,"") | O32: =SUM(F39+L39) -> 0
F33: =IF(E33="", "", VLOOKUP(E33, GradingTable!$A$2:$B$14, 2, FALSE)) | G33: =IF(AND(ISNUMBER(D33),ISNUMBER(F33)),D33*F33,"") | L33: =IF(K33="", "", VLOOKUP(K33, GradingTable!$A$2:$B$14, 2, FALSE)) | M33: =IF(AND(ISNUMBER(J33),ISNUMBER(L33)),J33*L33,"")
F34: =IF(E34="", "", VLOOKUP(E34, GradingTable!$A$2:$B$14, 2, FALSE)) | G34: =IF(AND(ISNUMBER(D34),ISNUMBER(F34)),D34*F34,"") | L34: =IF(K34="", "", VLOOKUP(K34, GradingTable!$A$2:$B$14, 2, FALSE)) | M34: =IF(AND(ISNUMBER(J34),ISNUMBER(L34)),J34*L34,"") | O34: Year 2 cGPA
F35: =IF(E35="", "", VLOOKUP(E35, GradingTable!$A$2:$B$14, 2, FALSE)) | G35: =IF(AND(ISNUMBER(D35),ISNUMBER(F35)),D35*F35,"") | L35: =IF(K35="", "", VLOOKUP(K35, GradingTable!$A$2:$B$14, 2, FALSE)) | M35: =IF(AND(ISNUMBER(J35),ISNUMBER(L35)),J35*L35,"") | O35: =IFERROR( (IF(ISNUMBER(F39*F40), F39*F40, 0) + IF(ISNUMBER(L39*L40), L39*L40, 0)) / (IF(ISNUMBER(F39), F39, 0) + IF(ISNUMBER(L39), L39, 0)), 0) -> 0
F36: =IF(E36="", "", VLOOKUP(E36, GradingTable!$A$2:$B$14, 2, FALSE)) | G36: =IF(AND(ISNUMBER(D36),ISNUMBER(F36)),D36*F36,"") | L36: =IF(K36="", "", VLOOKUP(K36, GradingTable!$A$2:$B$14, 2, FALSE)) | M36: =IF(AND(ISNUMBER(J36),ISNUMBER(L36)),J36*L36,"")
F37: =IF(E37="", "", VLOOKUP(E37, GradingTable!$A$2:$B$14, 2, FALSE)) | G37: =IF(AND(ISNUMBER(D37),ISNUMBER(F37)),D37*F37,"") | L37: =IF(K37="", "", VLOOKUP(K37, GradingTable!$A$2:$B$14, 2, FALSE)) | M37: =IF(AND(ISNUMBER(J37),ISNUMBER(L37)),J37*L37,"")
D39: Total Term Hours | F39: =SUM(D29:D38) -> 0 | J39: Total Term Hours | L39: =SUM(J29:J38) -> 0
D40: Term GPA | F40: =IF(F39=0, "", SUM(G29:G38)/F39) | J40: Term GPA | L40: =IF(L39=0, "", SUM(M29:M38)/L39)
B42: Year 3
C44: Term 5 | I44: Term 6
C45: Course | D45: Credits | E45: Grade | F45: Point | G45: Total | I45: Course | J45: Credits | K45: Grade | L45: Point | M45: Total
F46: =IF(E46="", "", VLOOKUP(E46, GradingTable!$A$2:$B$14, 2, FALSE)) | G46: =IF(AND(ISNUMBER(D46),ISNUMBER(F46)),D46*F46,"") | L46: =IF(K46="", "", VLOOKUP(K46, GradingTable!$A$2:$B$14, 2, FALSE)) | M46: =IF(AND(ISNUMBER(J46),ISNUMBER(L46)),J46*L46,"")
F47: =IF(E47="", "", VLOOKUP(E47, GradingTable!$A$2:$B$14, 2, FALSE)) | G47: =IF(AND(ISNUMBER(D47),ISNUMBER(F47)),D47*F47,"") | L47: =IF(K47="", "", VLOOKUP(K47, GradingTable!$A$2:$B$14, 2, FALSE)) | M47: =IF(AND(ISNUMBER(J47),ISNUMBER(L47)),J47*L47,"")
F48: =IF(E48="", "", VLOOKUP(E48, GradingTable!$A$2:$B$14, 2, FALSE)) | G48: =IF(AND(ISNUMBER(D48),ISNUMBER(F48)),D48*F48,"") | L48: =IF(K48="", "", VLOOKUP(K48, GradingTable!$A$2:$B$14, 2, FALSE)) | M48: =IF(AND(ISNUMBER(J48),ISNUMBER(L48)),J48*L48,"") | O48: Year 3 Hours
F49: =IF(E49="", "", VLOOKUP(E49, GradingTable!$A$2:$B$14, 2, FALSE)) | G49: =IF(AND(ISNUMBER(D49),ISNUMBER(F49)),D49*F49,"") | L49: =IF(K49="", "", VLOOKUP(K49, GradingTable!$A$2:$B$14, 2, FALSE)) | M49: =IF(AND(ISNUMBER(J49),ISNUMBER(L49)),J49*L49,"") | O49: =SUM(F56+L56) -> 0
F50: =IF(E50="", "", VLOOKUP(E50, GradingTable!$A$2:$B$14, 2, FALSE)) | G50: =IF(AND(ISNUMBER(D50),ISNUMBER(F50)),D50*F50,"") | L50: =IF(K50="", "", VLOOKUP(K50, GradingTable!$A$2:$B$14, 2, FALSE)) | M50: =IF(AND(ISNUMBER(J50),ISNUMBER(L50)),J50*L50,"")
F51: =IF(E51="", "", VLOOKUP(E51, GradingTable!$A$2:$B$14, 2, FALSE)) | G51: =IF(AND(ISNUMBER(D51),ISNUMBER(F51)),D51*F51,"") | L51: =IF(K51="", "", VLOOKUP(K51, GradingTable!$A$2:$B$14, 2, FALSE)) | M51: =IF(AND(ISNUMBER(J51),ISNUMBER(L51)),J51*L51,"") | O51: Year 3 cGPA
...

Sheet GradingTable
A1: Grade | B1: Point
A2: A+ | B2: 4
A3: A | B3: 4
A4: A- | B4: 3.7
A5: B+ | B5: 3.3
A6: B | B6: 3
A7: B- | B7: 2.7
A8: C+ | B8: 2.3
A9: C | B9: 2
A10: C- | B10: 1.7
A11: D+ | B11: 1.3
A12: D | B12: 1
A13: F | B13: 0
